<robot name="miniRobot_4Dof">
<link name="base">
<!-- Shapes for base -->
<collision>
<origin xyz="-0.020000000000000000416 0 0.0015000000000000000312" rpy="0 -0 0" />
<geometry>
<box size="0.2000000000000000111 0.080000000000000001665 0.0030000000000000000625" />
</geometry>
</collision>
<!-- Shapes for xl430_body -->
<collision>
<origin xyz="-0.012000000000000513728 -1.6819797354520329251e-18 0.020600000000000041889" rpy="-2.2496396739927918856e-32 -1.2246467991474145904e-16 -1.5707963267948983344" />
<geometry>
<box size="0.029000000000000001471 0.046499999999999999667 0.033000000000000001554" />
</geometry>
</collision>
<visual>
<origin xyz="0 0 0" rpy="0 -0 0" />
<geometry>
<mesh filename="package:///base_visual.stl"/>
</geometry>
<material name="base_material">
<color rgba="0.30196078431372547213 0.30196078431372547213 0.30196078431372547213 1.0"/>
</material>
</visual>
<inertial>
<origin xyz="-0.00071378491183774254135 -5.8777743782038403376e-19 0.036377739528460628637" rpy="0 0 0"/>
<mass value="0.06052526261743295527" />
<inertia ixx="1.0791964340195552799e-05" ixy="1.7514580000001528753e-07"  ixz="-1.7045690017635841602e-06" iyy="1.9495426312322722398e-05" iyz="4.7120139939200100149e-08" izz="1.6100622351049450557e-05" />
</inertial>
</link>

<link name="zlink">
<!-- Shapes for fr12-h101k -->
<collision>
<origin xyz="-6.0537977652541594527e-18 1.1578854311596977418e-18 0.0063000000000099677655" rpy="-3.141592653589738493 -1.570796326794896336 0" />
<geometry>
<box size="0.0040000000000000000833 0.041000000000000001721 0.0240000000000000005" />
</geometry>
</collision>
<collision>
<origin xyz="-1.0427257705840164644e-15 0.019000000000000009936 0.019300000000009968903" rpy="-3.141592653589738493 -1.570796326794896336 0" />
<geometry>
<box size="0.02999999999999999889 0.0030000000000000000625 0.0240000000000000005" />
</geometry>
</collision>
<collision>
<origin xyz="1.0369023657804154738e-15 -0.019000000000000006467 0.019300000000009965434" rpy="-3.141592653589738493 -1.570796326794896336 0" />
<geometry>
<box size="0.02999999999999999889 0.0030000000000000000625 0.0240000000000000005" />
</geometry>
</collision>
<!-- Shapes for xl430_horn -->
<collision>
<origin xyz="8.7306540035719714976e-16 -0.01675000000000890707 0.032300000000009994328" rpy="1.57079632679489678 5.1609789741048186761e-16 5.4248272540746913405e-14" />
<geometry>
<cylinder length="0.0040000000000000000833" radius="0.01025000000000000043" />
</geometry>
</collision>
<!-- Shapes for xl430_iddler -->
<collision>
<origin xyz="-8.0647768736611419589e-16 0.016499999999997638084 0.032300000000009952694" rpy="1.570796326794896558 -4.8834232179485246106e-16 -3.141592653589738493" />
<geometry>
<cylinder length="0.0030000000000000000625" radius="0.010500000000000000652" />
</geometry>
</collision>
<!-- Shapes for xl430_horn -->
<collision>
<origin xyz="3.3881317890172013563e-21 5.4234187233944558475e-34 0.0022499999999999976616" rpy="-6.1629758220391547298e-33 -0 -1.570796326794896558" />
<geometry>
<cylinder length="0.0040000000000000000833" radius="0.01025000000000000043" />
</geometry>
</collision>
<visual>
<origin xyz="0 0 0" rpy="0 -0 0" />
<geometry>
<mesh filename="package:///zlink_visual.stl"/>
</geometry>
<material name="zlink_material">
<color rgba="0.56931546743900030005 0.56931546743900030005 0.56931546743900030005 1.0"/>
</material>
</visual>
<inertial>
<origin xyz="-3.9013340700719669387e-07 -0.00061546666285507145577 0.015286391271556730095" rpy="0 0 0"/>
<mass value="0.012313797278541920022" />
<inertia ixx="4.7010563035976022511e-06" ixy="2.9567165488684286093e-12"  ixz="-6.2627133082855141052e-11" iyy="2.3947233113091281538e-06" iyz="1.2894157610858288857e-07" izz="3.4089197879256507103e-06" />
</inertial>
</link>

<link name="link">
<!-- Shapes for xl430_horn -->
<collision>
<origin xyz="0.068828101539235450601 -0.00033139703521166738844 0.0016406038814825202495" rpy="1.4055423491754413644e-13 -1.283695372226149874e-15 -1.5707963267948681363" />
<geometry>
<cylinder length="0.0040000000000000000833" radius="0.01025000000000000043" />
</geometry>
</collision>
<!-- Shapes for xl430_iddler -->
<collision>
<origin xyz="0.06882810153923853147 -0.00033139703520932919803 -0.0316093961185369976" rpy="-3.141592653589738493 1.427642726259330351e-13 1.5707963267948352737" />
<geometry>
<cylinder length="0.0030000000000000000625" radius="0.010500000000000000652" />
</geometry>
</collision>
<!-- Shapes for fr12-h101k -->
<collision>
<origin xyz="0.042828101539234997297 -0.00033139703521172317064 -0.015109396118522888317" rpy="-1.570796326794926534 -2.8803348595118822954e-14 4.9404924595820396905e-15" />
<geometry>
<box size="0.0040000000000000000833 0.041000000000000001721 0.0240000000000000005" />
</geometry>
</collision>
<collision>
<origin xyz="0.055828101539234453732 -0.0003313970352110896171 0.0038906038814774824425" rpy="-1.570796326794926534 -2.8803348595118822954e-14 4.9404924595820396905e-15" />
<geometry>
<box size="0.02999999999999999889 0.0030000000000000000625 0.0240000000000000005" />
</geometry>
</collision>
<collision>
<origin xyz="0.055828101539235536199 -0.00033139703521222819201 -0.03410939611852251141" rpy="-1.570796326794926534 -2.8803348595118822954e-14 4.9404924595820396905e-15" />
<geometry>
<box size="0.02999999999999999889 0.0030000000000000000625 0.0240000000000000005" />
</geometry>
</collision>
<!-- Shapes for fr12-s102k -->
<collision>
<origin xyz="0.03532810153921953078 -0.00033139703520941463316 -0.015109396118517854149" rpy="3.141592653589783346 -1.5707963267947409047 0" />
<geometry>
<box size="0.036999999999999998168 0.028000000000000000583 0.011499999999999999806" />
</geometry>
</collision>
<!-- Shapes for xl430_body -->
<collision>
<origin xyz="0.012028101539211761423 -0.00033139703520893015742 -0.014700000000000006464" rpy="1.9417017718966046491e-30 -1.4846281247441891857e-31 1.570796326794896558" />
<geometry>
<box size="0.029000000000000001471 0.046499999999999999667 0.033000000000000001554" />
</geometry>
</collision>
<visual>
<origin xyz="0 0 0" rpy="0 -0 0" />
<geometry>
<mesh filename="package:///link_visual.stl"/>
</geometry>
<material name="link_material">
<color rgba="0.345759014545379606 0.34485302042229559749 0.34183304001201569866 1.0"/>
</material>
</visual>
<inertial>
<origin xyz="0.010807558936928434237 -0.00033139703520846319155 -0.0014837921207062712038" rpy="0 0 0"/>
<mass value="0.073384953109897593793" />
<inertia ixx="1.6688147929585237986e-05" ixy="1.7514579999876932854e-07"  ixz="1.1106361068921108409e-05" iyy="5.5211375462477505275e-05" iyz="-4.8111619999441671868e-08" izz="4.6799797846820725381e-05" />
</inertial>
</link>

<link name="link_2">
<!-- Shapes for xl430_horn -->
<collision>
<origin xyz="0.06882810153918414442 -0.00033139703521496363409 0.001640603881475950418" rpy="-1.627725731978408191e-13 1.5762391392116192622e-13 -1.5707963267950613151" />
<geometry>
<cylinder length="0.0040000000000000000833" radius="0.01025000000000000043" />
</geometry>
</collision>
<!-- Shapes for xl430_iddler -->
<collision>
<origin xyz="0.068828101539179314949 -0.00033139703520829248392 -0.0316093961185303432" rpy="3.1415926535897913396 2.2898349882901466154e-15 1.5707963267949156538" />
<geometry>
<cylinder length="0.0030000000000000000625" radius="0.010500000000000000652" />
</geometry>
</collision>
<!-- Shapes for fr12-h101k -->
<collision>
<origin xyz="0.042828101539182289459 -0.0003313970352076660319 -0.015109396118521800645" rpy="-1.5707963267948166219 8.854722510774365729e-14 -1.8579582317103410867e-13" />
<geometry>
<box size="0.0040000000000000000833 0.041000000000000001721 0.0240000000000000005" />
</geometry>
</collision>
<collision>
<origin xyz="0.055828101539183952462 -0.00033139703521159659004 0.0038906038814770314144" rpy="-1.5707963267948166219 8.854722510774365729e-14 -1.8579582317103410867e-13" />
<geometry>
<box size="0.02999999999999999889 0.0030000000000000000625 0.0240000000000000005" />
</geometry>
</collision>
<collision>
<origin xyz="0.055828101539180545465 -0.00033139703520856624496 -0.034109396118522934682" rpy="-1.5707963267948166219 8.854722510774365729e-14 -1.8579582317103410867e-13" />
<geometry>
<box size="0.02999999999999999889 0.0030000000000000000625 0.0240000000000000005" />
</geometry>
</collision>
<!-- Shapes for fr12-s102k -->
<collision>
<origin xyz="0.035328101539201600678 -0.00033139703520788542021 -0.015109396118518816921" rpy="3.1415926535897797933 -1.5707963267947764319 0" />
<geometry>
<box size="0.036999999999999998168 0.028000000000000000583 0.011499999999999999806" />
</geometry>
</collision>
<!-- Shapes for xl430_body -->
<collision>
<origin xyz="0.012028101539211789178 -0.00033139703520893015742 -0.01470000000000000473" rpy="-6.9744079816962494488e-31 -1.1089657520201113554e-29 1.570796326794896558" />
<geometry>
<box size="0.029000000000000001471 0.046499999999999999667 0.033000000000000001554" />
</geometry>
</collision>
<visual>
<origin xyz="0 0 0" rpy="0 -0 0" />
<geometry>
<mesh filename="package:///link_2_visual.stl"/>
</geometry>
<material name="link_2_material">
<color rgba="0.345759014545379606 0.34485302042229559749 0.34183304001201569866 1.0"/>
</material>
</visual>
<inertial>
<origin xyz="0.010807558936919295714 -0.0003313970352080778661 -0.0014837921207063859124" rpy="0 0 0"/>
<mass value="0.073384953109897593793" />
<inertia ixx="1.6688147929584838187e-05" ixy="1.7514579999790871659e-07"  ixz="1.1106361068912070568e-05" iyy="5.5211375462422407475e-05" iyz="-4.8111619998809070605e-08" izz="4.6799797846766000276e-05" />
</inertial>
</link>

<link name="hand">
<!-- Shapes for thumb_3dprint -->
<collision>
<origin xyz="0.139799999999947272 -1.5464520825809974505e-14 0.0013906038814837755335" rpy="3.0734371785011327823e-14 0.174532707342721638 -1.2758406172634305222e-13" />
<geometry>
<box size="0.042000000000000002609 0.025000000000000001388 0.0020000000000000000416" />
</geometry>
</collision>
<collision>
<origin xyz="0.098799999999947304974 -1.0038350438915479776e-14 0.0018906038814834810746" rpy="3.0734371785011403554e-14 -0.17453270734273609865 -1.3781475231029705943e-13" />
<geometry>
<box size="0.042000000000000002609 0.025000000000000001388 0.0020000000000000000416" />
</geometry>
</collision>
<!-- Shapes for fr12-s102k -->
<collision>
<origin xyz="0.035299999999984815746 -2.3546720129274917046e-15 -0.015109396118517212301" rpy="1.4543921622589345576e-14 1.5707963267948590325 0" />
<geometry>
<box size="0.036999999999999998168 0.028000000000000000583 0.011499999999999999806" />
</geometry>
</collision>
<!-- Shapes for xc330-t288-t -->
<collision>
<origin xyz="0.060799999999954681962 -9.756084828893563099e-15 -0.015109396118516870561" rpy="-1.5707963267950306729 -1.5707963267948676922 0" />
<geometry>
<box size="0.020000000000000000416 0.034000000000000002442 0.022999999999999999611" />
</geometry>
</collision>
<!-- Shapes for fpx330-s102 -->
<collision>
<origin xyz="0.04379999999996986304 -4.1633363423443370266e-15 -0.01510939611851696944" rpy="1.5707963267946243313 -1.5707963267948648056 0" />
<geometry>
<box size="0.020000000000000000416 0.0050000000000000001041 0.028000000000000000583" />
</geometry>
</collision>
<!-- Shapes for xl430_body -->
<collision>
<origin xyz="0.01200000000000000025 -1.0991822286965487627e-33 -0.01470000000000000126" rpy="2.2642498892957820369e-30 1.1222980737868589143e-32 1.570796326794896558" />
<geometry>
<box size="0.029000000000000001471 0.046499999999999999667 0.033000000000000001554" />
</geometry>
</collision>
<visual>
<origin xyz="0 0 0" rpy="0 -0 0" />
<geometry>
<mesh filename="package:///hand_visual.stl"/>
</geometry>
<material name="hand_material">
<color rgba="0.32433932422824135466 0.33279441714866736524 0.3387493872779651638 1.0"/>
</material>
</visual>
<inertial>
<origin xyz="0.030184211811712352569 0.0019029219334532701015 -0.003402062216800896214" rpy="0 0 0"/>
<mass value="0.096694557631171490497" />
<inertia ixx="1.9770131862605235104e-05" ixy="-6.8281677909814151019e-06"  ixz="1.8740506372050671423e-05" iyy="0.00018180953824364218187" iyz="2.1066331068921780056e-06" izz="0.00017479428262797021536" />
</inertial>
</link>

<link name="tip">
<inertial>
<origin xyz="0 0 0" rpy="0 0 0" />
<mass value="1e-9" />
<inertia ixx="0" ixy="0" ixz="0" iyy="0" iyz="0" izz="0" />
</inertial>
</link>
<joint name="tip_frame" type="fixed">
<origin xyz="0.15915703310731399434 -0.0025000000000179184445 -0.0025674807125642754024" rpy="3.0093982861255696406e-14 -7.2337968948465128042e-15 -1.326994070183200432e-13" />
<parent link="hand" />
<child link="tip" />
<axis xyz="0 0 0"/>
</joint>

<link name="fingers">
<!-- Shapes for fpx330-h101 -->
<collision>
<origin xyz="4.8941873188161592456e-15 0.0044999999999980715149 0.011600000000005366435" rpy="3.1415926535894671545 -2.6356694604599949043e-13 -3.1415926535897189531" />
<geometry>
<box size="0.020000000000000000416 0.025000000000000001388 0.034000000000000002442" />
</geometry>
</collision>
<!-- Shapes for pinza_small -->
<collision>
<origin xyz="-0.0054645391252614670258 0.0562073130635065768 0.020100000000023654501" rpy="1.5707963267952094188 -2.7916993773733548045e-13 1.4081440617935612192" />
<geometry>
<box size="0.068000000000000004885 0.010000000000000000208 0.0020000000000000000416" />
</geometry>
</collision>
<collision>
<origin xyz="0.0057158004071097799625 0.056204495103899403119 0.020100000000020705471" rpy="1.5707963267951015052 -3.6583207174617015542e-13 1.7397563670481868137" />
<geometry>
<box size="0.068000000000000004885 0.010000000000000000208 0.0020000000000000000416" />
</geometry>
</collision>
<!-- Shapes for xc330_idler -->
<collision>
<origin xyz="8.5842552079426811864e-15 -6.1012965694804757207e-15 0.024300000000003908751" rpy="3.1415926535894671545 -2.6356694604599949043e-13 -3.1415926535897189531" />
<geometry>
<cylinder length="0.0020000000000000000416" radius="0.0080000000000000001665" />
</geometry>
</collision>
<!-- Shapes for xc330_horn -->
<collision>
<origin xyz="-8.6736173798841259908e-19 1.4701460990575508782e-32 -0.0015000000000000000312" rpy="-1.1239489358173154033e-29 6.0786439754144778271e-30 -6.4273701342461072501e-18" />
<geometry>
<cylinder length="0.0020000000000000000416" radius="0.0080000000000000001665" />
</geometry>
</collision>
<!-- Shapes for pinza_small -->
<collision>
<origin xyz="-0.005464539125266186341 0.056207313063512454043 0.0021000000000236610648" rpy="1.5707963267952094188 -2.7916993773733522801e-13 1.408144061793560553" />
<geometry>
<box size="0.068000000000000004885 0.010000000000000000208 0.0020000000000000000416" />
</geometry>
</collision>
<collision>
<origin xyz="0.0057158004071050511063 0.056204495103905280362 0.0021000000000207129022" rpy="1.5707963267951015052 -3.6583207174616985249e-13 1.7397563670481859255" />
<geometry>
<box size="0.068000000000000004885 0.010000000000000000208 0.0020000000000000000416" />
</geometry>
</collision>
<visual>
<origin xyz="0 0 0" rpy="0 -0 0" />
<geometry>
<mesh filename="package:///fingers_visual.stl"/>
</geometry>
<material name="fingers_material">
<color rgba="0.61490598060471968189 0.75554852060639132727 0.56686011639044830979 1.0"/>
</material>
</visual>
<inertial>
<origin xyz="4.7399627644084340824e-05 0.034433127929634918529 0.011526404890807020673" rpy="0 0 0"/>
<mass value="0.017427434309548597152" />
<inertia ixx="1.1094193187189511311e-05" ixy="-1.1419802617426554558e-09"  ixz="-6.0776732720561551615e-11" iyy="2.6230686363094648348e-06" iyz="-4.4182816982331121561e-08" izz="9.9034961953929639836e-06" />
</inertial>
</link>

<joint name="m5" type="revolute">
<origin xyz="0.068299999999956229058 0.011499999999989227173 -0.015109396118516508004" rpy="-1.5707963267959674791 1.5448496502901225558 3.1415926535884723947" />
<parent link="hand" />
<child link="fingers" />
<axis xyz="0 0 1"/>
<limit effort="0.92000000000000003997" velocity="6.8067799999999998306" lower="-2.0943951023931952626" upper="0.1745329251994329478"/>
<joint_properties friction="0.0"/>
</joint>

<joint name="m4" type="revolute">
<origin xyz="0.068828101539183769719 -0.00033139703521460617264 -0.00060939611852404290682" rpy="1.5642385810831845659e-13 1.7150654904405390804e-13 8.3266726846495145048e-17" />
<parent link="link_2" />
<child link="hand" />
<axis xyz="0 0 1"/>
<limit effort="1.3999999999999999112" velocity="5.969030000000000058" lower="-2.0071286397934788859" upper="2.0071286397934788859"/>
<joint_properties friction="0.0"/>
</joint>

<joint name="m3" type="revolute">
<origin xyz="0.068828101539235783668 -0.00033139703521166408162 -0.00060939611851748218263" rpy="-1.6069805841221960239e-13 -3.0422611836434535438e-13 2.8975346409153908838e-14" />
<parent link="link" />
<child link="link_2" />
<axis xyz="0 0 1"/>
<limit effort="1.3999999999999999112" velocity="5.969030000000000058" lower="-2.0071286397934788859" upper="2.0071286397934788859"/>
<joint_properties friction="0.0"/>
</joint>

<joint name="m2" type="revolute">
<origin xyz="7.4121820335150412351e-16 -0.014500000000007283105 0.032296892735896400028" rpy="1.5707963267948981123 2.9585411036258416433e-14 1.9762598289744061984e-13" />
<parent link="zlink" />
<child link="link" />
<axis xyz="0 0 1"/>
<limit effort="1.3999999999999999112" velocity="5.969030000000000058" lower="-0.43633231299858238339" upper="3.5779249665883754439"/>
<joint_properties friction="0.0"/>
</joint>

<joint name="m1_continuous" type="continuous">
<origin xyz="2.8101539209724824345e-05 -0.00033139703520890673866 0.035300000000000060496" rpy="1.096373512893316052e-15 -5.3478581229248155831e-17 8.2282813188807744652e-14" />
<parent link="base" />
<child link="zlink" />
<axis xyz="0 0 1"/>
<limit effort="1.3999999999999999112" velocity="5.969030000000000058" />
<joint_properties friction="0.0"/>
</joint>


</robot>
